Traceback (most recent call last):
  File "/beagle3/haky/users/shared_pipelines/enformer_pipeline_aggregate/scripts/enformer_predict.py", line 277, in <module>
    main()
  File "/beagle3/haky/users/shared_pipelines/enformer_pipeline_aggregate/scripts/enformer_predict.py", line 216, in main
    exec_futures = [q.result() for q in sample_app_futures] 
  File "/beagle3/haky/users/shared_pipelines/enformer_pipeline_aggregate/scripts/enformer_predict.py", line 216, in <listcomp>
    exec_futures = [q.result() for q in sample_app_futures] 
  File "/beagle3/haky/users/shared_software/TFXcan-pipeline-tools/lib/python3.9/concurrent/futures/_base.py", line 439, in result
    return self.__get_result()
  File "/beagle3/haky/users/shared_software/TFXcan-pipeline-tools/lib/python3.9/concurrent/futures/_base.py", line 391, in __get_result
    raise self._exception
  File "/beagle3/haky/users/shared_software/TFXcan-pipeline-tools/lib/python3.9/site-packages/parsl/dataflow/dflow.py", line 297, in handle_exec_update
    res = self._unwrap_remote_exception_wrapper(future)
  File "/beagle3/haky/users/shared_software/TFXcan-pipeline-tools/lib/python3.9/site-packages/parsl/dataflow/dflow.py", line 491, in _unwrap_remote_exception_wrapper
    result = future.result()
  File "/beagle3/haky/users/shared_software/TFXcan-pipeline-tools/lib/python3.9/concurrent/futures/_base.py", line 439, in result
    return self.__get_result()
  File "/beagle3/haky/users/shared_software/TFXcan-pipeline-tools/lib/python3.9/concurrent/futures/_base.py", line 391, in __get_result
    raise self._exception
  File "/beagle3/haky/users/shared_software/TFXcan-pipeline-tools/lib/python3.9/site-packages/parsl/executors/high_throughput/executor.py", line 450, in _queue_management_worker
    s.reraise()
  File "/beagle3/haky/users/shared_software/TFXcan-pipeline-tools/lib/python3.9/site-packages/parsl/app/errors.py", line 128, in reraise
    reraise(t, v, v.__traceback__)
  File "/beagle3/haky/users/shared_software/TFXcan-pipeline-tools/lib/python3.9/site-packages/six.py", line 719, in reraise
    raise value
  File "/beagle3/haky/users/shared_software/TFXcan-pipeline-tools/bin/process_worker_pool.py", line 392, in worker_watchdog
    raise WorkerLost(worker_id, platform.node())
parsl.executors.high_throughput.errors.WorkerLost: Task failure due to loss of worker 2 on host beagle3-0028.rcc.local
